Workbook

Sheet Intake
A1: Pacfa ID | B1: Name | C1: Address | D1: City | E1: State | F1: Zip | G1: Dogs Beg. Inven. | H1: Dogs Stray | I1: Dogs Owner Surr./Adop Ret. | J1: Dogs Confiscate/Protec. Cust. | K1: Dogs Trans. In from in state | L1: Dogs Trans. In from out of state | M1: Dogs Other | N1: Dogs Total Intake | O1: Cats Beg. Inven. | P1: Cats Stray | Q1: Cats Owner Surr./Adop Ret. | R1: Cats Confiscate/Protec. Cust. | S1: Cats Trans. In from in state | T1: Cats Trans. In from out of state | U1: Cats Other | V1: Cats Total Intake | W1: Small Mammals Beg. Inven. | X1: Small Mammals Stray | Y1: Small Mammals Owner Surr./Adop Ret. | Z1: Small Mammals Confiscate/Protec. Cust. | AA1: Small Mammals Trans. In from in state | AB1: Small Mammals Trans. In from out of state | AC1: Small Mammals Other | AD1: Small Mammals Total Intake | AE1: Reptiles Beg. Inven. | AF1: Reptiles Stray | AG1: Reptiles Owner Surr./Adop Ret. | AH1: Reptiles Confiscate/Protec. Cust. | AI1: Reptiles Trans. In from in state | AJ1: Reptiles Trans. In from out of state | AK1: Reptiles Other | AL1: Reptiles Total Intake | AM1: Pet Birds Beg. Inven. | AN1: Pet Birds Stray | AO1: Pet Birds Owner Surr./Adop Ret. | AP1: Pet Birds Confiscate/Protec. Cust. | AQ1: Pet Birds Trans. In from in state | AR1: Pet Birds Trans. In from out of state | AS1: Pet Birds Other | AT1: Pet Birds Total Intake | AU1: Column1
A2: 6948 | B2: 4 Paws 4 Life Rescue | C2: 3000 S Jamaica Ct, Ste 140 | D2: Aurora | E2: CO | F2: 80014 | G2: 0 | H2: 2 | I2: 4 | J2: 0 | K2: 91 | L2: 443 | N2: 540
A3: 4636 | B3: 4 PAWS RESCUE | C3: 1332 Imperial Dr. | D3: COLORADO SPRINGS | E3: CO | F3: 80918 | G3: 3 | H3: 0 | I3: 22 | J3: 0 | K3: 0 | L3: 0 | M3: 0 | N3: 25
A4: 2540 | B4: 9 LIVES RESCUE | C4: 2159 BROOKWOOD DR. | D4: COLORADO SPRINGS | E4: CO | F4: 80918
A5: 6051 | B5: A Puppy's Voice | C5: 9048 W. 101st Ave. | D5: Westminster | E5: CO | F5: 80021 | G5: 2 | L5: 826 | N5: 828
A6: 6522 | B6: A Soft Place to Land | C6: 1122 W. Myrtle St. | D6: Fort Collins | E6: CO | F6: 80521 | G6: 31 | H6: 0 | I6: 13 | J6: 0 | K6: 8 | L6: 10 | M6: 0 | N6: 31 | O6: 0 | P6: 0 | Q6: 0 | R6: 0 | S6: 0 | T6: 0 | U6: 0 | V6: 0 | X6: 0 | Y6: 0 | Z6: 0 | AA6: 0 | AB6: 0 | AC6: 0 | AD6: 0 | AE6: 0 | AF6: 0 | AG6: 0 | AH6: 0 | AI6: 0 | AJ6: 0 | AK6: 0 | AL6: 0 | AM6: 0 | AN6: 0 | AO6: 0 | AP6: 0 | AQ6: 0 | AR6: 0 | AS6: 0 | AT6: 0
A7: 4184 | B7: ADAMS COUNTY ANIMAL SHELTER & ADOPTION CENTER | C7: 10705 FULTON | D7: BRIGHTON | E7: CO | F7: 80601 | G7: 146 | H7: 2533 | I7: 538 | J7: 175 | K7: 1 | L7: 0 | M7: 376 | N7: 3623 | O7: 220 | P7: 2078 | Q7: 291 | R7: 38 | S7: 1 | T7: 0 | U7: 295 | V7: 2703 | W7: 1 | X7: 30 | Y7: 6 | Z7: 5 | AA7: 5 | AB7: 0 | AC7: 18 | AD7: 64 | AE7: 0 | AF7: 2 | AG7: 1 | AH7: 4 | AI7: 0 | AJ7: 0 | AK7: 0 | AL7: 7 | AM7: 0 | AN7: 6 | AO7: 1 | AP7: 3 | AQ7: 0 | AR7: 0 | AS7: 1 | AT7: 11
A8: 6831 | B8: All Ears Basset Sanctuary | C8: 8625 W. 1st Ave | D8: Lakewood | E8: CO | F8: 80226 | G8: 12 | H8: 0 | I8: 9 | J8: 0 | K8: 17 | L8: 121 | M8: 0 | N8: 159
A9: 6795 | B9: Almost Home Adoptions for Rescued Cats | C9: 6010 W. 88th Ave. | D9: Westminster | E9: CO | F9: 80021 | O9: 111 | P9: 502 | Q9: 60 | V9: 673
A10: 4541 | B10: ANGELS WITH PAWS | C10: 2540 YOUNGFIELD ST. | D10: LAKEWOOD | E10: CO | F10: 80215 | O10: 61 | P10: 153 | Q10: 196 | R10: 0 | S10: 434 | T10: 53 | U10: 12
A11: 1161 | B11: ANIMAL CLINIC OF JULESBURG | C11: 809 W 3RD ST. | D11: JULESBURG | E11: CO | F11: 80737
A12: 5597 | B12: Animal House Pets & Grooming, Inc. | C12: 1104 W. Vine Dr. | D12: FORT COLLINS | E12: CO | F12: 80521 | G12: 58 | H12: 1 | I12: 98 | J12: 0 | K12: 81 | L12: 325 | M12: 0
A13: 4855 | B13: ANIMAL LOVING PEOPLE HELPING ANIMALS (ALPHA) HUMANE | C13: 0086 SO. RD. 1 EAST | D13: MONTE VISTA | E13: CO | F13: 81144
A14: 626 | B14: ANIMAL RESCUE & ADOPTION SOCIETY | C14: 2390 S. DELAWARE | D14: DENVER | E14: CO | F14: 80223 | O14: 63 | P14: 8 | Q14: 263 | R14: 0 | S14: 13 | T14: 0 | U14: 0 | V14: 284
A15: 5937 | B15: Animal Rescue Connection, Inc. | C15: 4095 W. 16th St. Rd | D15: Greeley | E15: CO | F15: 80634 | G15: 0 | N15: 0 | O15: 0 | P15: 88 | Q15: 0 | R15: 0 | S15: 0 | T15: 0 | U15: 0 | V15: 0 | W15: 88 | X15: 13 | Y15: 0 | Z15: 0 | AA15: 0 | AC15: 0 | AD15: 0 | AE15: 0 | AF15: 0 | AG15: 0 | AH15: 0 | AI15: 0 | AJ15: 0 | AK15: 0 | AL15: 0 | AM15: 0 | AN15: 0 | AO15: 0 | AP15: 0 | AQ15: 0 | AR15: 0 | AS15: 0 | AT15: 0
A16: 5667 | B16: Animal Rescue of the Rockies | C16: 0577A Broken Lance | D16: BRECKENRIDGE | E16: CO | F16: 80424 | G16: 145 | H16: 25 | I16: 27 | J16: 0 | K16: 450 | L16: 25 | M16: 0 | N16: 527 | O16: 17 | P16: 11 | Q16: 9 | R16: 0 | S16: 133 | T16: 0 | U16: 0 | V16: 153
A17: 26 | B17: ANIMAL WELFARE & PROTECTION SOCIETY | C17: 3420 W. 8TH ST. | D17: PUEBLO | E17: CO | F17: 81003 | G17: 43 | H17: 310 | I17: 665 | J17: 0 | K17: 13 | L17: 0 | M17: 0 | N17: 988 | O17: 0 | P17: 11 | V17: 11
A18: 3912 | B18: ANNIE'S ORPHANS | C18: 1630 CR 214 | D18: DURANGO | E18: CO | F18: 81303 | G18: 68 | H18: 10 | I18: 32 | K18: 1 | L18: 7 | M18: 25 | N18: 75
A19: 1726 | B19: ARK VALLEY HUMANE SOCIETY | C19: 701 GREGG DR | D19: BUENA VISTA | E19: CO | F19: 81211 | G19: 12 | H19: 144 | I19: 141 | J19: 3 | K19: 96 | L19: 0 | M19: 8 | N19: 392 | O19: 28 | P19: 98 | Q19: 112 | R19: 0 | S19: 128 | T19: 0 | U19: 0 | V19: 338 | W19: 0 | X19: 2 | Y19: 2 | Z19: 0 | AA19: 0 | AB19: 0 | AC19: 0 | AD19: 4 | AE19: 0 | AF19: 0 | AG19: 0 | AH19: 0 | AI19: 0 | AJ19: 0 | AK19: 0 | AL19: 0 | AM19: 0 | AN19: 0 | AO19: 2 | AP19: 0 | AQ19: 0 | AR19: 0 | AS19: 0 | AT19: 0
A20: 6624 | B20: Ark Valley Humane Society dba The Sunshine Shelter | C20: 10128 US Hwy 50 | D20: Poncha Springs | E20: CO | F20: 81242 | G20: 5 | H20: 168 | I20: 37 | J20: 0 | K20: 17 | L20: 0 | M20: 2 | N20: 224 | O20: 46 | P20: 160 | Q20: 116 | R20: 0 | S20: 33 | T20: 0 | U20: 0 | V20: 309 | W20: 0 | X20: 0 | Y20: 0 | Z20: 0 | AA20: 0 | AB20: 0 | AC20: 0 | AD20: 0 | AE20: 0 | AF20: 0 | AG20: 0 | AH20: 0 | AI20: 0 | AJ20: 0 | AK20: 0 | AL20: 0 | AM20: 0 | AN20: 0 | AO20: 0 | AP20: 0 | AQ20: 0 | AR20: 0 | AS20: 0 | AT20: 0
A21: 5332 | B21: ASPEN BOARDING KENNEL & ANIMAL SHELTER | C21: 101 ANIMAL SHELTER RD., SUITE 1 | D21: ASPEN | E21: CO | F21: 81611 | G21: 34 | H21: 105 | I21: 44 | J21: 4 | K21: 32 | L21: 17 | M21: 0 | N21: 236 | O21: 17 | P21: 39 | Q21: 43 | R21: 0 | S21: 1 | T21: 0 | U21: 0 | V21: 100 | W21: 0 | X21: 0 | Y21: 0 | Z21: 0 | AA21: 0 | AB21: 0 | AC21: 0 | AD21: 0 | AE21: 0 | AF21: 1 | AG21: 3 | AH21: 0 | AI21: 0 | AJ21: 0 | AK21: 0 | AL21: 4 | AM21: 0 | AN21: 2 | AO21: 4 | AP21: 0 | AQ21: 0 | AR21: 0 | AS21: 0 | AT21: 6
A22: 4663 | B22: AVON PET CENTRE | C22: 730 NOTTINGHAM RD. | D22: AVON | E22: CO | F22: 81620 | I22: 5
A23: 1759 | B23: BARNWATER CATS | C23: 3131 E EVANS AVE | D23: DENVER | E23: CO | F23: 80210
A24: 1629 | B24: BEAR CREEK ANIMAL HOSPITAL | C24: 2430 E VICTORY WAY | D24: CRAIG | E24: CO | F24: 81625 | H24: 390 | N24: 390 | P24: 196 | V24: 196 | X24: 5 | AD24: 5
A25: 6129 | B25: Best Friends Forever | C25: 6350 Oak St. #206 | D25: Arvada | E25: CO | F25: 80004 | G25: 8 | H25: 0 | I25: 0 | J25: 0 | K25: 11 | L25: 50 | M25: 0 | N25: 61
A26: 2972 | B26: BICHON FRISE GET AWAY & RESCUE RANCH | C26: 1979 CARLSON RD. | D26: PARKER | E26: CO | F26: 80138
A27: 6038 | B27: Big Dogs Huge Paws | C27: 17756 E. Ida Ave. | D27: Centennial | E27: CO | F27: 80015
A28: 7085 | B28: Biscuit's Safe Haven Rescue | C28: 13611 Parkview Pl | D28: Broomfield | E28: CO | F28: 80023 | G28: 3 | H28: 5 | I28: 2 | K28: 21 | L28: 6 | N28: 37
A29: 6347 | B29: Black Canyon Animal Sanctuary | C29: 42528 Needle Rock Rd. | D29: Crawford | E29: CO | F29: 81415 | G29: 43 | H29: 36 | I29: 39 | K29: 22 | L29: 7 | N29: 147
A30: 3960 | B30: BLUE LION ANIMAL RESCUE | C30: 33955 TORRENCE RD. | D30: YODER | E30: CO | F30: 80864 | G30: 104 | I30: 8 | K30: 10 | L30: 55 | M30: 7 | N30: 80
A31: 6346 | B31: Breeder Release Adoption Service | C31: 18500 CR 47.7 | D31: Bon Carbo | E31: CO | F31: 81024 | G31: 110 | H31: 0 | I31: 0 | J31: 0 | K31: 27 | L31: 620 | M31: 0 | N31: 647
A32: 4295 | B32: C.A.W.S. (CITIZENS FOR ANIMAL WELFARE & SHELTER) | C32: 42528 NEEDLE ROCK RD. | D32: CRAWFORD | E32: CO | F32: 81415
A33: 4573 | B33: CALICO FIELD ANIMAL SHELTER | C33: 12330 RAMAH HWY. | D33: CALHAN | E33: CO | F33: 80808 | G33: 52 | H33: 0 | I33: 0 | J33: 0 | K33: 0 | L33: 0 | M33: 1 | N33: 53 | O33: 0 | P33: 0 | Q33: 0 | R33: 0 | S33: 0 | T33: 0 | U33: 0 | V33: 0 | W33: 0 | X33: 0 | Y33: 0 | Z33: 0 | AA33: 0 | AB33: 0 | AC33: 0 | AD33: 0 | AE33: 0 | AG33: 0 | AH33: 0 | AI33: 0 | AJ33: 0 | AK33: 0 | AL33: 0 | AM33: 0 | AN33: 0 | AO33: 0 | AP33: 0 | AQ33: 0 | AR33: 0 | AS33: 0 | AT33: 0
A34: 6682 | B34: Canine Candor, Inc. | C34: 4947 West C Street | D34: Greeley | E34: CO | F34: 80634 | G34: 5 | H34: 3 | I34: 14 | J34: 0 | K34: 21 | L34: 25 | N34: 68
A35: 500 | B35: CARBON VALLEY ANIMAL HOSPITAL | C35: 101 W. GRANT AVE | D35: FIRESTONE | E35: CO | F35: 80520
A36: 3945 | B36: CAT CARE SOCIETY | C36: 5787 W. 6TH AVE. | D36: LAKEWOOD | E36: CO | F36: 80214 | G36: 0 | H36: 0 | I36: 0 | J36: 0 | K36: 0 | L36: 0 | M36: 0 | N36: 0 | O36: 74 | P36: 190 | Q36: 143 | R36: 0 | S36: 5 | T36: 0 | U36: 13 | V36: 351
A37: 3027 | B37: CAVY CARE INC. | C37: 4343 S. JASPER ST. | D37: AURORA | E37: CO | F37: 80015 | G37: 0 | H37: 0 | I37: 0 | J37: 0 | K37: 0 | L37: 0 | M37: 0 | N37: 0 | O37: 0 | P37: 0 | Q37: 0 | R37: 0 | S37: 0 | T37: 0 | U37: 0 | V37: 0 | W37: 170 | X37: 0 | Y37: 0 | Z37: 0 | AA37: 30 | AB37: 0 | AC37: 0 | AD37: 200 | AE37: 0 | AF37: 0 | AG37: 0 | AH37: 0 | AI37: 0 | AJ37: 0 | AK37: 0 | AL37: 0 | AM37: 0 | AN37: 0 | AO37: 0 | AP37: 0 | AQ37: 0 | AR37: 0 | AS37: 0 | AT37: 0
A38: 1852 | B38: CHARLOTTE WILLIAMS ANIMAL REFUGE | C38: 33210 CO. RD. 34 | D38: MATHESON | E38: CO | F38: 80830 | G38: 36 | N38: 0 | O38: 5 | V38: 0
A39: 5406 | B39: CHIHUAHUA & SMALL DOG RESCUE, INC. | C39: 53 MONK ST. | D39: COLORADO SPRINGS | E39: CO | F39: 80911
A40: 6423 | B40: Christie O'Rourke | C40: 8753 County Road 74/82 | D40: Elbert | E40: CO | F40: 80106
...

Sheet Outflow
A1: Pacfa ID | B1: Name | C1: Address | D1: City | E1: State | F1: Zip | G1: Dogs RTO | H1: Dogs Adopted | I1: Dogs Euthanized | J1: Dogs DOA | K1: Dogs Died | L1: Dogs Trans. In state | M1: Dogs Trans. Out of state | N1: Dogs Other (missing, stolen, etc.) | O1: Dogs Total Outcomes | P1: Dogs Ending Inventory | Q1: Cats RTO | R1: Cats Adopted | S1: Cats Euthanized | T1: Cats DOA | U1: Cats Died | V1: Cats Trans. In state | W1: Cats Trans. Out of state | X1: Cats Other (missing, stolen, etc.) | Y1: Cats Total Outcomes | Z1: Cats Ending Inventory | AA1: Small Mammals RTO | AB1: Small Mammals Adopted | AC1: Small Mammals Euthanized | AD1: Small Mammals DOA | AE1: Small Mammals Died | AF1: Small Mammals Trans. In state | AG1: Small Mammals Trans. Out of state | AH1: Small Mammals Other (missing, stolen, etc.) | AI1: Small Mammals Total Outcomes | AJ1: Small Mammals Ending Inventory | AK1: Reptiles RTO | AL1: Reptiles Adopted | AM1: Reptiles Euthanized | AN1: Reptiles DOA | AO1: Reptiles Died | AP1: Reptiles Trans. In state | AQ1: Reptiles Trans. Out of state | AR1: Reptiles Other (missing, stolen, etc.) | AS1: Reptiles Total Outcomes | AT1: Reptiles Ending Inventory | AU1: Pet Birds RTO | AV1: Pet Birds Adopted | AW1: Pet Birds Euthanized | AX1: Pet Birds DOA | AY1: Pet Birds Died | AZ1: Pet Birds Trans. In state | BA1: Pet Birds Trans. Out of state | BB1: Pet Birds Other (missing, stolen, etc.) | BC1: Pet Birds Total Outcomes | BD1: Pet Birds Ending Inventory | BE1: Column1
A2: 2 | B2: HUMANE SOCIETY OF BOULDER VALLEY | C2: 2323 55TH ST | D2: BOULDER | E2: CO | F2: 80301 | G2: 940 | H2: 4138 | I2: 258 | J2: 90 | K2: 9 | L2: 84 | M2: 3 | N2: 96 | O2: 5618 | P2: 65 | Q2: 318 | R2: 2313 | S2: 330 | T2: 119 | U2: 19 | V2: 7 | W2: 1 | X2: 77 | Y2: 3184 | Z2: 87 | AA2: 16 | AB2: 272 | AC2: 26 | AD2: 10 | AE2: 11 | AF2: 28 | AG2: 0 | AH2: 12 | AI2: 375 | AJ2: 3 | AK2: 2 | AL2: 2 | AM2: 1 | AN2: 0 | AO2: 0 | AP2: 5 | AQ2: 0 | AR2: 2 | AS2: 12 | AT2: 0 | AU2: 11 | AV2: 31 | AW2: 3 | AX2: 3 | AY2: 2 | AZ2: 11 | BA2: 0 | BB2: 0 | BC2: 61 | BD2: 0
A3: 6 | B3: DUMB FRIENDS LEAGUE/HUMANE SOCIETY OF DENVER | C3: 2080 S. QUEBEC ST | D3: DENVER | E3: CO | F3: 80231 | G3: 1397 | H3: 6005 | I3: 1009 | J3: 269 | K3: 26 | L3: 263 | M3: 0 | N3: 1135 | O3: 10104 | P3: 185 | Q3: 373 | R3: 5947 | S3: 2011 | T3: 141 | U3: 66 | V3: 131 | W3: 0 | X3: 552 | Y3: 9221 | Z3: 307 | AA3: 12 | AB3: 841 | AC3: 476 | AD3: 30 | AE3: 29 | AF3: 128 | AG3: 0 | AH3: 53 | AI3: 1569 | AJ3: 34 | AK3: 0 | AL3: 5 | AM3: 1 | AN3: 4 | AO3: 0 | AP3: 24 | AQ3: 0 | AR3: 0 | AS3: 34 | AT3: 7 | AU3: 1 | AV3: 7 | AW3: 7 | AX3: 7 | AY3: 2 | AZ3: 133 | BA3: 0 | BB3: 0 | BC3: 157 | BD3: 2
A4: 7 | B4: HUMANE SOCIETY OF THE PIKES PEAK REGION | C4: 610 ABBOTT LANE | D4: COLORADO SPRINGS | E4: CO | F4: 80905 | G4: 3247 | H4: 3539 | I4: 1244 | J4: 118 | K4: 17 | L4: 72 | M4: 3 | N4: 1275 | O4: 9515 | P4: 94 | Q4: 1749 | R4: 3131 | S4: 2021 | T4: 149 | U4: 57 | V4: 288 | W4: 0 | X4: 858 | Y4: 8253 | Z4: 95 | AA4: 77 | AB4: 310 | AC4: 69 | AD4: 9 | AE4: 12 | AF4: 1 | AG4: 0 | AH4: 190 | AI4: 668 | AJ4: 18 | AK4: 18 | AL4: 49 | AM4: 4 | AN4: 0 | AO4: 0 | AP4: 0 | AQ4: 0 | AR4: 14 | AS4: 85 | AT4: 3 | AU4: 19 | AV4: 78 | AW4: 4 | AX4: 1 | AY4: 2 | AZ4: 0 | BA4: 0 | BB4: 8 | BC4: 112 | BD4: 1
A5: 8 | B5: HUMANE SOCIETY OF FREMONT COUNTY | C5: 110 RHOADES AVE. | D5: CANON CITY | E5: CO | F5: 81212 | G5: 537 | H5: 790 | I5: 170 | J5: 132 | K5: 12 | L5: 138 | M5: 0 | N5: 243 | O5: 2022 | P5: 76 | Q5: 23 | R5: 261 | S5: 619 | T5: 90 | U5: 5 | V5: 338 | W5: 0 | X5: 221 | Y5: 1557 | Z5: 28 | AA5: 8 | AB5: 7 | AC5: 1 | AD5: 73 | AE5: 0 | AF5: 7 | AG5: 0 | AH5: 14 | AI5: 110 | AJ5: 4 | AK5: 0 | AL5: 0 | AM5: 0 | AN5: 0 | AO5: 0 | AP5: 0 | AQ5: 0 | AR5: 0 | AS5: 0 | AT5: 0 | AU5: 0 | AV5: 0 | AW5: 0 | AX5: 0 | AY5: 0 | AZ5: 0 | BA5: 0 | BB5: 0 | BC5: 0 | BD5: 0
A6: 12 | B6: CITY OF GUNNISON ANIMAL SHELTER | C6: 1100 W. VIRGINIA AVE. | D6: GUNNISON | E6: CO | F6: 81230 | G6: 155 | H6: 9 | I6: 0 | J6: 0 | K6: 2 | L6: 0 | M6: 0 | N6: 0 | O6: 166 | P6: 0 | Q6: 9 | R6: 23 | S6: 3 | T6: 0 | U6: 8 | V6: 0 | W6: 0 | X6: 0 | Y6: 43 | Z6: 0 | AU6: 1 | AV6: 0 | AW6: 0 | AX6: 0 | AY6: 0 | AZ6: 0 | BA6: 0 | BB6: 0 | BC6: 1 | BD6: 0
A7: 16 | B7: LA PLATA COUNTY HUMANE SOCIETY | C7: 1111 S. CAMINO DEL RIO | D7: DURANGO | E7: CO | F7: 81303 | G7: 0
A8: 17 | B8: LARIMER HUMANE SOCIETY | C8: 6317 KYLE AVE | D8: FORT COLLINS | E8: CO | F8: 80525 | G8: 1689 | H8: 1024 | I8: 269 | J8: 99 | K8: 3 | L8: 183 | M8: 11 | N8: 214 | O8: 3492 | P8: 47 | Q8: 422 | R8: 1437 | S8: 413 | T8: 174 | U8: 17 | V8: 102 | W8: 0 | X8: 154 | Y8: 2719 | Z8: 77 | AA8: 17 | AB8: 215 | AC8: 25 | AD8: 26 | AE8: 11 | AF8: 6 | AG8: 0 | AH8: 7 | AI8: 807 | AJ8: 9 | AK8: 74 | AL8: 109 | AM8: 4 | AN8: 3 | AO8: 7 | AP8: 3 | AQ8: 1 | AR8: 0 | AS8: 201 | AT8: 0 | AU8: 277 | AV8: 137 | AW8: 18 | AX8: 23 | AY8: 3 | AZ8: 0 | BA8: 0 | BB8: 15 | BC8: 473 | BD8: 3
A9: 25 | B9: CITY OF LAMAR ANIMAL SHELTER | C9: 8551 RD. EE.5 | D9: LAMAR | E9: CO | F9: 81052 | G9: 172 | H9: 32 | I9: 1 | J9: 0 | K9: 0 | L9: 122 | M9: 0 | N9: 2 | O9: 329 | P9: 8 | Q9: 0 | R9: 0 | S9: 0 | T9: 0 | U9: 0 | V9: 0 | W9: 0 | X9: 0 | Y9: 0 | Z9: 0 | AA9: 0 | AB9: 0 | AC9: 0 | AD9: 0 | AE9: 0 | AF9: 0 | AG9: 0 | AH9: 0 | AI9: 0 | AJ9: 0 | AK9: 0 | AL9: 0 | AM9: 0 | AN9: 0 | AO9: 0 | AP9: 0 | AQ9: 0 | AR9: 0 | AS9: 0 | AT9: 0 | AU9: 0 | AV9: 0 | AW9: 0 | AX9: 0 | AY9: 0 | AZ9: 0 | BA9: 0 | BB9: 0 | BC9: 0 | BD9: 0
A10: 26 | B10: ANIMAL WELFARE & PROTECTION SOCIETY | C10: 3420 W. 8TH ST. | D10: PUEBLO | E10: CO | F10: 81003 | G10: 53 | H10: 912 | I10: 3 | J10: 0 | K10: 7 | L10: 17 | M10: 0 | N10: 2 | O10: 494 | P10: 37 | R10: 11 | Y10: 11 | Z10: 0
A11: 30 | B11: CITY OF STEAMBOAT SPRINGS ANIMAL SHELTER | C11: 760 CRITTER CT | D11: STEAMBOAT SPRINGS | E11: CO | F11: 80477 | G11: 248 | H11: 87 | I11: 4 | K11: 0 | L11: 6 | M11: 0 | O11: 345 | P11: 6 | Q11: 17 | R11: 208 | S11: 8 | U11: 1 | V11: 16 | W11: 0 | Y11: 250 | Z11: 22 | AB11: 10 | AI11: 10
A12: 31 | B12: TOWN OF TELLURIDE ANIMAL SHELTER | C12: 12000 HWY 145 | D12: TELLURIDE | E12: CO | F12: 81435 | G12: 35 | H12: 0 | I12: 1 | J12: 0 | K12: 0 | L12: 3 | M12: 0 | N12: 0 | O12: 0 | P12: 1
A13: 32 | B13: SUMMIT COUNTY ANIMAL SHELTER | C13: 0191 SCR 1004 | D13: FRISCO | E13: CO | F13: 80443 | G13: 200 | H13: 141 | I13: 4 | J13: 3 | K13: 0 | L13: 8 | M13: 0 | N13: 0 | O13: 356 | P13: 18 | Q13: 18 | R13: 81 | S13: 4 | T13: 4 | U13: 1 | V13: 0 | W13: 0 | X13: 0 | Y13: 108 | Z13: 17 | AA13: 0 | AB13: 9 | AC13: 0 | AD13: 0 | AE13: 0 | AF13: 3 | AG13: 0 | AH13: 0 | AI13: 12 | AJ13: 2 | AK13: 0 | AL13: 0 | AM13: 0 | AN13: 0 | AO13: 0 | AP13: 0 | AQ13: 0 | AR13: 0 | AS13: 0 | AT13: 0 | AU13: 0 | AV13: 0 | AW13: 0 | AX13: 0 | AY13: 0 | AZ13: 0 | BA13: 0 | BB13: 0 | BC13: 0 | BD13: 0
A14: 38 | B14: CITY OF AURORA ANIMAL SHELTER | C14: 15750 E. 32ND AVE. | D14: AURORA | E14: CO | F14: 80011 | G14: 921 | H14: 637 | I14: 397 | J14: 66 | K14: 4 | L14: 396 | N14: 2 | O14: 2423 | P14: 53 | Q14: 89 | R14: 171 | S14: 631 | T14: 34 | U14: 4 | V14: 378 | W14: 0 | X14: 1 | Y14: 1308 | Z14: 22 | AA14: 6 | AB14: 49 | AC14: 121 | AD14: 21 | AE14: 1 | AF14: 156 | AI14: 354 | AJ14: 0 | AK14: 1 | AL14: 0 | AM14: 5 | AN14: 0 | AO14: 1 | AP14: 0 | AQ14: 0 | AR14: 0 | AS14: 7 | AT14: 0 | AU14: 23 | AV14: 23 | AW14: 9 | AX14: 2 | AY14: 0 | AZ14: 19 | BA14: 0 | BB14: 0 | BC14: 76 | BD14: 0
A15: 42 | B15: CITY OF BRIGHTON ANIMAL SHELTER | C15: 325 1/2 N. KUNER RD. | D15: BRIGHTON | E15: CO | F15: 80601 | G15: 257 | H15: 11 | I15: 58 | J15: 32 | K15: 3 | L15: 128 | M15: 0 | N15: 1 | O15: 478 | P15: 0 | Q15: 24 | R15: 0 | S15: 80 | T15: 39 | U15: 1 | V15: 126 | W15: 0 | X15: 0 | Y15: 267 | Z15: 0 | AA15: 0 | AB15: 1 | AC15: 3 | AD15: 57 | AE15: 1 | AF15: 18 | AG15: 0 | AH15: 0 | AI15: 80 | AJ15: 0
A16: 48 | B16: CITY OF ROCKY FORD ANIMAL SHELTER | C16: 203 S. 9TH STREET | D16: ROCKY FORD | E16: CO | F16: 81067 | G16: 35 | H16: 9 | I16: 1 | J16: 0 | K16: 0 | L16: 42 | M16: 0 | N16: 0 | O16: 87 | P16: 0
A17: 52 | B17: HIGHLAND VETERINARY CLINIC, P.C. | C17: 206 2ND ST | D17: AULT | E17: CO | F17: 80610 | G17: 31 | H17: 6 | I17: 2 | L17: 3 | P17: 2 | Q17: 0 | R17: 4 | S17: 5 | V17: 17 | Z17: 2 | AB17: 1 | AC17: 0 | AJ17: 0 | AM17: 0 | AT17: 0 | AW17: 0 | BD17: 0
A18: 283 | B18: COLORADO DOG ACADEMY, INC. | C18: 12180 N. SHERIDAN | D18: BROOMFIELD | E18: CO | F18: 80020
A19: 291 | B19: Valley Vet Clinic | C19: 7038 Hwy 160 | D19: Alamosa | E19: CO | F19: 81101
A20: 316 | B20: MOUNTAIN SHADOWS ANIMAL HOSPITAL | C20: 9171 U.S. HWY 50 | D20: SALIDA | E20: CO | F20: 81201
A21: 476 | B21: HALLCREST KENNELS | C21: 2046 COUNTY RD. 158 | D21: ELIZABETH | E21: CO | F21: 80107
A22: 500 | B22: CARBON VALLEY ANIMAL HOSPITAL | C22: 101 W. GRANT AVE | D22: FIRESTONE | E22: CO | F22: 80520
A23: 540 | B23: ST Francis Hotel for Pets Boarding Kennel | C23: 14851 CR G | H23: 3 | I23: 3 | K23: 1 | P23: 21 | U23: 3 | Z23: 9
A24: 626 | B24: ANIMAL RESCUE & ADOPTION SOCIETY | C24: 2390 S. DELAWARE | D24: DENVER | E24: CO | F24: 80223 | Q24: 1 | R24: 251 | S24: 9 | T24: 1 | U24: 6 | V24: 1 | W24: 0 | X24: 0 | Y24: 0 | Z24: 96
A25: 638 | B25: CITY OF MONTROSE ANIMAL SHELTER | C25: 3383 NORTH TOWNSEND AVE | D25: MONTROSE | E25: CO | F25: 81401 | G25: 323 | H25: 216 | I25: 10 | J25: 4 | K25: 2 | L25: 78 | M25: 0 | N25: 1 | O25: 634 | P25: 16 | Q25: 27 | R25: 197 | S25: 74 | T25: 30 | U25: 11 | V25: 325 | W25: 0 | X25: 0 | Y25: 664 | Z25: 13 | AA25: 1 | AB25: 5 | AC25: 0 | AD25: 0 | AE25: 0 | AF25: 0 | AG25: 0 | AH25: 0 | AI25: 6 | AJ25: 0 | AK25: 0 | AL25: 0 | AM25: 0 | AN25: 0 | AO25: 0 | AP25: 0 | AQ25: 0 | AR25: 0 | AS25: 0 | AT25: 0 | AU25: 0 | AV25: 0 | AW25: 0 | AX25: 1 | AY25: 0 | AZ25: 0 | BA25: 0 | BB25: 0 | BC25: 1 | BD25: 0
A26: 639 | B26: NORTH FORK VETERINARY CLINIC | C26: 14926 BETHLEHEM RD. | D26: PAONIA | E26: CO | F26: 81428 | G26: 6 | H26: 4 | I26: 0 | J26: 0 | K26: 0 | L26: 0 | M26: 0 | N26: 0 | O26: 10 | P26: 0 | Q26: 0 | R26: 1 | S26: 0 | T26: 0 | U26: 0 | V26: 0 | W26: 0 | X26: 0 | Y26: 10 | Z26: 0
A27: 705 | B27: TOWN OF LIMON ANIMAL SHELTER - I | C27: 701 INDIANA AVE | D27: LIMON | E27: CO | F27: 80828 | G27: 28 | H27: 11 | N27: 8 | O27: 47 | P27: 0
A28: 857 | B28: D N R KENNELS | C28: 115 GATEWAY DR | D28: BRECKENRIDGE | E28: CO | F28: 80424 | G28: 0 | H28: 0 | I28: 0 | J28: 0 | K28: 0 | L28: 0 | M28: 2 | N28: 0 | O28: 2 | P28: 0 | Q28: 1 | R28: 1 | S28: 0 | T28: 0 | U28: 0 | V28: 0 | W28: 0 | X28: 0 | Y28: 1 | Z28: 0
A29: 1108 | B29: LONGMONT HUMANE SOCIETY | C29: 9595 NELSON RD | D29: LONGMONT | E29: CO | F29: 80501 | G29: 696 | H29: 1165 | I29: 81 | J29: 92 | K29: 2 | L29: 100 | N29: 38 | O29: 2174 | P29: 107 | Q29: 99 | R29: 1169 | S29: 141 | T29: 128 | U29: 11 | V29: 99 | X29: 17 | Y29: 1664 | Z29: 123 | AA29: 1 | AB29: 88 | AC29: 6 | AD29: 5 | AE29: 2 | AF29: 27 | AI29: 129 | AJ29: 6 | AV29: 29 | AW29: 1 | AX29: 1 | AY29: 1 | AZ29: 3 | BB29: 1 | BC29: 36 | BD29: 6
A30: 1161 | B30: ANIMAL CLINIC OF JULESBURG | C30: 809 W 3RD ST. | D30: JULESBURG | E30: CO | F30: 80737
A31: 1166 | B31: Land of Ahs Kennel | C31: 12599 Jordan Rd | D31: Fountain | E31: CO | F31: 80817 | G31: 122 | H31: 7 | I31: 17 | L31: 96 | O31: 242 | Q31: 24 | R31: 4 | S31: 3 | V31: 132 | Y31: 163 | Z31: 3 | BE31: 2-other
A32: 1183 | B32: NORTHWEST ANIMAL HOSPITAL, PC | C32: 4575 N CHESTNUT ST | D32: COLORADO SPRINGS | E32: CO | F32: 80907
A33: 1317 | B33: WESTIE RESCUE NETWORK, INC | C33: 7895 Mustang Rd. | D33: COLORADO SPRINGS | E33: CO | F33: 80908 | G33: 1 | H33: 73 | I33: 2 | K33: 1 | L33: 3 | O33: 80 | P33: 3 | R33: 1 | Y33: 1 | Z33: 0
A34: 1506 | B34: TENAKER PET CARE CENTER, INC. | C34: 895 LAREDO | D34: AURORA | E34: CO | F34: 80011
A35: 1629 | B35: BEAR CREEK ANIMAL HOSPITAL | C35: 2430 E VICTORY WAY | D35: CRAIG | E35: CO | F35: 81625 | G35: 207 | H35: 137 | I35: 13 | L35: 30 | N35: 3 | P35: 390 | Q35: 3 | R35: 84 | S35: 21 | V35: 76 | X35: 12 | Z35: 196 | AB35: 5 | AJ35: 5
A36: 1699 | B36: CITY OF CRIPPLE CREEK ANIMAL SHELTER | C36: 550 HAYDEN | D36: CRIPPLE CREEK | E36: CO | F36: 80813 | G36: 26 | H36: 9 | O36: 35 | P36: 0 | R36: 1 | V36: 2 | Y36: 3 | Z36: 0
A37: 1719 | B37: INTERMOUNTAIN HUMANE SOCIETY | C37: 67318 US HWY 285 | D37: PINE | E37: CO | F37: 80470 | G37: 32 | H37: 238 | I37: 1 | J37: 0 | K37: 0 | L37: 16 | M37: 0 | N37: 0 | O37: 287 | P37: 0 | Q37: 13 | R37: 379 | S37: 4 | T37: 0 | U37: 4 | V37: 1 | W37: 0 | X37: 1 | Y37: 402 | Z37: 55 | AA37: 0 | AB37: 0 | AC37: 0 | AD37: 0 | AE37: 0 | AF37: 0 | AG37: 0 | AH37: 0 | AI37: 0 | AJ37: 0 | AK37: 0 | AL37: 0 | AM37: 0 | AN37: 0 | AO37: 0 | AP37: 0 | AQ37: 0 | AR37: 0 | AS37: 0 | AT37: 0 | AU37: 0 | AV37: 0 | AW37: 0 | AX37: 0 | AY37: 0 | AZ37: 0 | BA37: 0 | BB37: 0 | BC37: 0 | BD37: 0
A38: 1726 | B38: ARK VALLEY HUMANE SOCIETY | C38: 701 GREGG DR | D38: BUENA VISTA | E38: CO | F38: 81211 | G38: 118 | H38: 220 | I38: 17 | J38: 1 | K38: 1 | L38: 29 | M38: 0 | N38: 1 | O38: 387 | P38: 19 | Q38: 9 | R38: 226 | S38: 13 | T38: 3 | U38: 7 | V38: 84 | W38: 0 | X38: 0 | Y38: 342 | Z38: 27 | AA38: 2 | AB38: 2 | AC38: 0 | AD38: 0 | AE38: 0 | AF38: 0 | AG38: 0 | AH38: 0 | AI38: 4 | AJ38: 0 | AK38: 0 | AL38: 0 | AM38: 0 | AN38: 0 | AO38: 0 | AP38: 0 | AQ38: 0 | AR38: 0 | AS38: 0 | AT38: 0 | AU38: 0 | AV38: 2 | AW38: 0 | AX38: 0 | AY38: 0 | AZ38: 0 | BA38: 0 | BB38: 0 | BC38: 2 | BD38: 0
A39: 1731 | B39: CITY OF LA JUNTA ANIMAL SHELTER | C39: 30227 6TH AVE | D39: LA JUNTA | E39: CO | F39: 81050
A40: 1759 | B40: BARNWATER CATS | C40: 3131 E EVANS AVE | D40: DENVER | E40: CO | F40: 80210
...

Sheet Counts-Averages
A1: Intake | D1: Outflow
A2: Dogs | D2: Dogs
A3: Beg. Inventory | B3: =SUM(Intake!G283) -> 0 | D3: RTO | E3: =SUM(Outflow!G284) -> 0
A4: Stray | B4: =SUM(Intake!H283) -> 0 | D4: Adopt | E4: =SUM(Outflow!H284) -> 0
A5: Owner Surren./Adop. Ret. | B5: =SUM(Intake!I283) -> 0 | D5: Euth | E5: =SUM(Outflow!I284) -> 0
A6: Confiscate/Protec. Custody | B6: =SUM(Intake!J283) -> 0 | D6: DOA | E6: =SUM(Outflow!J284) -> 0
A7: Trans. In from In State | B7: =SUM(Intake!K283) -> 0 | D7: Died | E7: =SUM(Outflow!K284) -> 0
A8: Trans from Out of state | B8: =SUM(Intake!L283) -> 0 | D8: Trans. In State | E8: =SUM(Outflow!L284) -> 0
A9: Dogs Other | B9: =SUM(Intake!M283) -> 0 | D9: Trans. Out of State | E9: =SUM(Outflow!M284) -> 0
A10: Dogs Total Intake | B10: =SUM(Intake!N283) -> 0 | D10: Other (missing, stolen, etc) | E10: =SUM(Outflow!N284) -> 0
D11: Dogs Total Outcomes | E11: =SUM(Outflow!O284) -> 0
A12: Cats | D12: Dogs Ending Inventory | E12: =SUM(Outflow!P284) -> 0
A13: Beg. Inventory | B13: =SUM(Intake!O283) -> 0
A14: Stray | B14: =SUM(Intake!P283) -> 0 | D14: Cats
A15: Owner Surren./Adop. Ret. | B15: =SUM(Intake!Q283) -> 0 | D15: RTO | E15: =SUM(Outflow!Q284) -> 0
A16: Confiscate/Protec. Custody | B16: =SUM(Intake!R283) -> 0 | D16: Adopt | E16: =SUM(Outflow!R284) -> 0
A17: Trans. In from In State | B17: =SUM(Intake!S283) -> 0 | D17: Euth | E17: =SUM(Outflow!S284) -> 0
A18: Trans from Out of state | B18: =SUM(Intake!T283) -> 0 | D18: DOA | E18: =SUM(Outflow!T284) -> 0
A19: Cats Other | B19: =SUM(Intake!U283) -> 0 | D19: Died | E19: =SUM(Outflow!U284) -> 0
A20: Cats Total Intake | B20: =SUM(Intake!V283) -> 0 | D20: Trans. In State | E20: =SUM(Outflow!V284) -> 0
D21: Trans. Out of State | E21: =SUM(Outflow!W284) -> 0
A22: Small Mammals | D22: Other (missing, stolen, etc) | E22: =SUM(Outflow!X284) -> 0
A23: Beg. Inventory | B23: =SUM(Intake!W283) -> 0 | D23: Cats Total Outcomes | E23: =SUM(Outflow!Y284) -> 0
A24: Stray | B24: =SUM(Intake!X283) -> 0 | D24: Cats Ending Inventory | E24: =SUM(Outflow!Z284) -> 0
A25: Owner Surren./Adop. Ret. | B25: =SUM(Intake!Y283) -> 0
A26: Confiscate/Protec. Custody | B26: =SUM(Intake!Z283) -> 0 | D26: Small Mammals
A27: Trans. In from In State | B27: =SUM(Intake!AA283) -> 0 | D27: RTO | E27: =SUM(Outflow!AA284) -> 0
A28: Trans from Out of state | B28: =SUM(Intake!AB283) -> 0 | D28: Adopt | E28: =SUM(Outflow!AB284) -> 0
A29: Small Mammals Other | B29: =SUM(Intake!AC283) -> 0 | D29: Euth | E29: =SUM(Outflow!AC284) -> 0
A30: Small Mammals Total | B30: =SUM(Intake!AD283) -> 0 | D30: DOA | E30: =SUM(Outflow!AD284) -> 0
D31: Died | E31: =SUM(Outflow!AE284) -> 0
A32: Reptiles | D32: Trans. In State | E32: =SUM(Outflow!AF284) -> 0
A33: Beg. Inventory | B33: =SUM(Intake!AE283) -> 0 | D33: Trans. Out of State | E33: =SUM(Outflow!AG284) -> 0
A34: Stray | B34: =SUM(Intake!AF283) -> 0 | D34: Other (missing, stolen, etc) | E34: =SUM(Outflow!AH284) -> 0
A35: Owner Surren./Adop. Ret. | B35: =SUM(Intake!AG283) -> 0 | D35: Sm. Mammals Total Outcome | E35: =SUM(Outflow!AI284) -> 0
A36: Confiscate/Protec. Custody | B36: =SUM(Intake!AH283) -> 0 | D36: Sm. Mammals Ending Inven. | E36: =SUM(Outflow!AJ284) -> 0
A37: Trans. In from In State | B37: =SUM(Intake!AI283) -> 0
A38: Trans from Out of state | B38: =SUM(Intake!AJ283) -> 0 | D38: Reptiles
A39: Reptiles Other | B39: =SUM(Intake!AK283) -> 0 | D39: RTO | E39: =SUM(Outflow!AK284) -> 0
A40: Reptiles Total Intake | B40: =SUM(Intake!AL283) -> 0 | D40: Adopt | E40: =SUM(Outflow!AL284) -> 0
...
